<?xml version="1.0" ?>
<!-- =================================================================================== -->
<!-- |    This document was autogenerated by xacro from robot.urdf.xacro               | -->
<!-- |    EDITING THIS FILE BY HAND IS NOT RECOMMENDED                                 | -->
<!-- =================================================================================== -->
<robot name="greenguardian">
  <link name="world"/>
  <material name="black">
    <color rgba="0 0 0 1"/>
  </material>
  <material name="grey">
    <color rgba="0.5 0.5 0.5 1"/>
  </material>
  <material name="white">
    <color rgba="1 1 1 1"/>
  </material>
  <material name="red">
    <color rgba="1 0 0 1"/>
  </material>
  <material name="green">
    <color rgba="0 1 0 1"/>
  </material>
  <material name="blue">
    <color rgba="0 0 1 1"/>
  </material>
  <link name="manipulator_base_link">
    <visual>
      <origin rpy="0 0 0" xyz="0 0 0.03965"/>
      <geometry>
        <box size="0.0285 0.0285 0.0793"/>
      </geometry>
      <material name="green"/>
    </visual>
    <collision>
      <origin rpy="0 0 0" xyz="0 0 0.03965"/>
      <geometry>
        <box size="0.0285 0.0285 0.0793"/>
      </geometry>
    </collision>
    <inertial>
      <origin rpy="0 0 0" xyz="0 0 0.03965"/>
      <mass value="1.0"/>
      <inertia ixx="0.0005917283333333333" ixy="0.0" ixz="0.0" iyy="0.0005917283333333333" iyz="0.0" izz="0.000135375"/>
    </inertial>
  </link>
  <link name="link_1">
    <visual>
      <origin rpy="0 0 0" xyz="0 0 0.015"/>
      <geometry>
        <box size="0.0285 0.035 0.03"/>
      </geometry>
      <material name="blue"/>
    </visual>
    <collision>
      <origin rpy="0 0 0" xyz="0 0 0.015"/>
      <geometry>
        <box size="0.0285 0.035 0.03"/>
      </geometry>
    </collision>
    <inertial>
      <origin rpy="0 0 0" xyz="0 0 0.015"/>
      <mass value="1.0"/>
      <inertia ixx="0.00017708333333333335" ixy="0.0" ixz="0.0" iyy="0.0001426875" iyz="0.0" izz="0.00016977083333333332"/>
    </inertial>
  </link>
  <link name="link_2">
    <visual>
      <origin rpy="0 0 0" xyz="0 0 0.0635"/>
      <geometry>
        <box size="0.0285 0.035 0.127"/>
      </geometry>
      <material name="red"/>
    </visual>
    <collision>
      <origin rpy="0 0 0" xyz="0 0 0.0635"/>
      <geometry>
        <box size="0.0285 0.035 0.127"/>
      </geometry>
    </collision>
    <inertial>
      <origin rpy="0 0 0" xyz="0 0 0.0635"/>
      <mass value="1.0"/>
      <inertia ixx="0.0014461666666666668" ixy="0.0" ixz="0.0" iyy="0.0014117708333333335" iyz="0.0" izz="0.00016977083333333332"/>
    </inertial>
  </link>
  <link name="link_3">
    <visual>
      <origin rpy="0 0 0" xyz="0 0 0.092075"/>
      <geometry>
        <box size="0.0285 0.035 0.18415"/>
      </geometry>
      <material name="grey"/>
    </visual>
    <collision>
      <origin rpy="0 0 0" xyz="0 0 0.092075"/>
      <geometry>
        <box size="0.0285 0.035 0.18415"/>
      </geometry>
    </collision>
    <inertial>
      <origin rpy="0 0 0" xyz="0 0 0.092075"/>
      <mass value="1.0"/>
      <inertia ixx="0.0029280185416666665" ixy="0.0" ixz="0.0" iyy="0.0028936227083333336" iyz="0.0" izz="0.00016977083333333332"/>
    </inertial>
  </link>
  <link name="link_4">
    <visual>
      <origin rpy="0 0 0" xyz="0 0 0.03175"/>
      <geometry>
        <box size="0.0285 0.035 0.0635"/>
      </geometry>
      <material name="red"/>
    </visual>
    <collision>
      <origin rpy="0 0 0" xyz="0 0 0.03175"/>
      <geometry>
        <box size="0.0285 0.035 0.0635"/>
      </geometry>
    </collision>
    <inertial>
      <origin rpy="0 0 0" xyz="0 0 0.03175"/>
      <mass value="1.0"/>
      <inertia ixx="0.0004381041666666667" ixy="0.0" ixz="0.0" iyy="0.0004037083333333333" iyz="0.0" izz="0.00016977083333333332"/>
    </inertial>
  </link>
  <link name="link_5">
    <visual>
      <origin rpy="0 0 0" xyz="0 0 0.05715"/>
      <geometry>
        <box size="0.0285 0.035 0.1143"/>
      </geometry>
      <material name="blue"/>
    </visual>
    <collision>
      <origin rpy="0 0 0" xyz="0 0 0.05715"/>
      <geometry>
        <box size="0.0285 0.035 0.1143"/>
      </geometry>
    </collision>
    <inertial>
      <origin rpy="0 0 0" xyz="0 0 0.05715"/>
      <mass value="1.0"/>
      <inertia ixx="0.0011907908333333333" ixy="0.0" ixz="0.0" iyy="0.001156395" iyz="0.0" izz="0.00016977083333333332"/>
    </inertial>
  </link>
  <!-- Joints -->
  <joint name="base_joint" type="fixed">
    <parent link="world"/>
    <origin rpy="0 0 0" xyz="0 0 0"/>
    <child link="manipulator_base_link"/>
    <axis xyz="0 0 1"/>
  </joint>
  <joint name="joint_1" type="revolute">
    <parent link="manipulator_base_link"/>
    <child link="link_1"/>
    <origin rpy="0 0 0" xyz="0 0 0.0793"/>
    <axis xyz="0 0 1"/>
    <limit effort="1000.0" lower="0.0" upper="3.141592653589793" velocity="2.5"/>
  </joint>
  <joint name="joint_2" type="revolute">
    <parent link="link_1"/>
    <child link="link_2"/>
    <origin rpy="0 3.141592653589793 0" xyz="0 0 0.03"/>
    <axis xyz="0 -1 0"/>
    <limit effort="1000.0" lower="0.0" upper="3.141592653589793" velocity="2.5"/>
  </joint>
  <joint name="joint_3" type="revolute">
    <parent link="link_2"/>
    <child link="link_3"/>
    <origin rpy="0 0 0" xyz="0 0 0.127"/>
    <axis xyz="0 1 0"/>
    <limit effort="1000.0" lower="0.0" upper="3.141592653589793" velocity="2.5"/>
  </joint>
  <joint name="joint_4" type="revolute">
    <parent link="link_3"/>
    <child link="link_4"/>
    <origin rpy="0 0 0" xyz="0 0 0.18415"/>
    <axis xyz="0 1 0"/>
    <limit effort="1000.0" lower="0.0" upper="3.141592653589793" velocity="2.5"/>
  </joint>
  <joint name="joint_5" type="revolute">
    <parent link="link_4"/>
    <child link="link_5"/>
    <origin rpy="0 0 0" xyz="0 0 0.0635"/>
    <axis xyz="0 0 1"/>
    <limit effort="1000.0" lower="0.0" upper="3.141592653589793" velocity="2.5"/>
  </joint>
  <ros2_control name="manipulator_ros2control" type="system">
    <hardware>
      <plugin>guardian/Pca9685SystemHardware</plugin>
      <param name="pca_frequency">50.0</param>
      <param name="jt_lower_limit">0.0</param>
      <param name="jt_upper_limit">3.141592653589793</param>
      <param name="joint_1__channel">0</param>
      <param name="joint_2__channel">4</param>
      <param name="joint_3__channel">12</param>
      <param name="joint_4__channel">5</param>
      <param name="joint_5__channel">7</param>
      <param name="joint_1__init_position">0.0</param>
      <param name="joint_2__init_position">3.1</param>
      <param name="joint_3__init_position">0.0</param>
      <param name="joint_4__init_position">0.0</param>
      <param name="joint_5__init_position">0.0</param>
    </hardware>
    <joint name="joint_1">
      <command_interface name="position">
        <param name="min">0.0</param>
        <param name="max">3.141592653589793</param>
      </command_interface>
      <state_interface name="position">
        <param name="initial_value">0.0</param>
      </state_interface>
    </joint>
    <joint name="joint_2">
      <command_interface name="position">
        <param name="min">0.0</param>
        <param name="max">3.141592653589793</param>
      </command_interface>
      <state_interface name="position">
        <param name="initial_value">3.1</param>
      </state_interface>
    </joint>
    <joint name="joint_3">
      <command_interface name="position">
        <param name="min">0.0</param>
        <param name="max">3.141592653589793</param>
      </command_interface>
      <state_interface name="position">
        <param name="initial_value">0.0</param>
      </state_interface>
    </joint>
    <joint name="joint_4">
      <command_interface name="position">
        <param name="min">0.0</param>
        <param name="max">3.141592653589793</param>
      </command_interface>
      <state_interface name="position">
        <param name="initial_value">0.0</param>
      </state_interface>
    </joint>
    <joint name="joint_5">
      <command_interface name="position">
        <param name="min">0.0</param>
        <param name="max">3.141592653589793</param>
      </command_interface>
      <state_interface name="position">
        <param name="initial_value">0.0</param>
      </state_interface>
    </joint>
  </ros2_control>
</robot>
